2023-08-21 23:25:06,796 [DEBUG] py4...: Calling cytoscape_ping()
2023-08-21 23:25:06,796 [DEBUG] py4...: ǀCalling cytoscape_version_info(base_url='http://127.0.0.1:1234/v1')
2023-08-21 23:25:06,797 [DEBUG] py4...: ǀǀCalling cyrest_get('version', base_url='http://127.0.0.1:1234/v1')
2023-08-21 23:25:06,797 [DEBUG] py4...: Attempting to direct connect to Cytoscape on http://127.0.0.1:1234/v1
2023-08-21 23:25:08,824 [DEBUG] py4...: Attempting to connect to remote Cytoscape because of error HTTPConnectionPool(host='127.0.0.1', port=1234): Max retries exceeded with url: /v1 (Caused by NewConnectionError('<urllib3.connection.HTTPConnection object at 0x00000287665A7310>: Failed to establish a new connection: [WinError 10061] No connection could be made because the target machine actively refused it'))
2023-08-21 23:25:08,824 [DEBUG] py4...: ǀǀHTTP GET(http://127.0.0.1:1234/v1)
2023-08-21 23:25:09,385 [DEBUG] py4...: Error initially contacting Jupyter-bridge: Error posting to Jupyter-bridge: Channel None:request contains unprocessed message
2023-08-21 23:25:09,386 [DEBUG] py4...: ǀǀ'cyrest_get' exception RequestException('Cannot find local or remote Cytoscape. Start Cytoscape and then proceed.')
2023-08-21 23:25:09,386 [DEBUG] py4...: ǀ'cytoscape_version_info' exception RequestException('Cannot find local or remote Cytoscape. Start Cytoscape and then proceed.')
2023-08-21 23:25:09,387 [DEBUG] py4...: 'cytoscape_ping' exception RequestException('Cannot find local or remote Cytoscape. Start Cytoscape and then proceed.')
2023-08-21 23:25:09,387 [DEBUG] py4...: --------------------
